Workbook

Sheet Hypothèses
A1: HYPOTHÈSES GÉNÉRALES
A2: Paramètre | B2: Valeur | C2: Unité
A3: Utilisateurs initiaux | B3: 500 | C3: users
A4: Croissance mensuelle | B4: 0.15 | C4: %
A5: Coût API Claude par voyage (Sonnet+Haiku) | B5: 0.3 | C5: €
A6: Coût SerpAPI par voyage | B6: 0.08 | C6: €
A7: Coût Booking API par voyage (30% des trips) | B7: 0.02 | C7: €
A8: Coût total API par voyage | B8: =B5+B6+B7 | C8: €
A9: Coût serveur mensuel fixe | B9: 50 | C9: €
A10: Voyages moyens par user free/mois | B10: 1 | C10: voyages
A11: Voyages moyens par user power/mois | B11: 3 | C11: voyages
A14: Modèle 1: Freemium + Abonnement (actuel)
A15: Paramètre | B15: Valeur | C15: Unité
A16: Taux conversion free→pro | B16: 0.05 | C16: %
A17: Churn mensuel pro | B17: 0.03 | C17: %
A18: Prix Pro annuel | B18: 9.99 | C18: €
A19: Prix Pro mensuel | B19: 1.99 | C19: €
A20: Part abonnés annuels | B20: 0.6 | C20: %
A21: Prix achat unitaire | B21: 0.99 | C21: €
A22: Achats unitaires par free user/mois | B22: 0.1 | C22: voyages
A23: Modèle 2: Gratuit + Publicité
A24: Paramètre | B24: Valeur | C24: Unité
A25: CPM (pour 1000 impressions) | B25: 3 | C25: €
A26: Pages vues par user/mois | B26: 10 | C26: pages
A27: Impressions pub par page | B27: 2 | C27: impressions
A28: Taux rétention mensuel | B28: 0.8 | C28: %
A29: Modèle 3: Paiement à l'unité
A30: Paramètre | B30: Valeur | C30: Unité
A31: Prix par voyage | B31: 1.99 | C31: €
A32: Voyages achetés par user actif/mois | B32: 1.5 | C32: voyages
A33: Taux users actifs payants | B33: 0.25 | C33: %
A34: Taux rétention mensuel | B34: 0.65 | C34: %
A35: Modèle 4: Hybride Abo + Pub
A36: Paramètre | B36: Valeur | C36: Unité
A37: Taux conversion free→pro | B37: 0.04 | C37: %
A38: Churn mensuel pro | B38: 0.03 | C38: %
A39: Prix Pro annuel (sans pub) | B39: 9.99 | C39: €
A40: CPM pub (free users) | B40: 3 | C40: €
A41: Pages vues free user/mois | B41: 10 | C41: pages
A42: Impressions pub par page | B42: 2 | C42: impressions
...

Sheet 1-Freemium+Abo
A1: Mois | B1: Users totaux | C1: Users free | D1: Users pro | E1: Nouveaux pro | F1: Churned pro | G1: Revenu abo (€) | H1: Revenu unitaire (€) | I1: Revenu total (€) | J1: Coût API (€) | K1: Coût serveur (€) | L1: Marge brute (€) | M1: Revenu cumulé (€)
A2: 1 | B2: ='Hypothèses'!B3 | C2: =B2-D2 | D2: =ROUND(B2*'Hypothèses'!B16,0) | E2: =ROUND(B2*'Hypothèses'!B16,0) | F2: 0 | G2: =D2*('Hypothèses'!B20*'Hypothèses'!B18/12+(1-'Hypothèses'!B20)*'Hypothèses'!B19) | H2: =C2*'Hypothèses'!B22*'Hypothèses'!B21 | I2: =G2+H2 | J2: =(C2*1+D2*3)*'Hypothèses'!B8 | K2: ='Hypothèses'!B9 | L2: =I2-J2-K2 | M2: =L2
A3: 2 | B3: =ROUND(B2*(1+'Hypothèses'!B4),0) | C3: =B3-D3 | D3: =MAX(0,D2+E3-F3) | E3: =ROUND((B3-D2)*'Hypothèses'!B16,0) | F3: =ROUND(D2*'Hypothèses'!B17,0) | G3: =D3*('Hypothèses'!B20*'Hypothèses'!B18/12+(1-'Hypothèses'!B20)*'Hypothèses'!B19) | H3: =C3*'Hypothèses'!B22*'Hypothèses'!B21 | I3: =G3+H3 | J3: =(C3*1+D3*3)*'Hypothèses'!B8 | K3: ='Hypothèses'!B9 | L3: =I3-J3-K3 | M3: =M2+L3
A4: 3 | B4: =ROUND(B3*(1+'Hypothèses'!B4),0) | C4: =B4-D4 | D4: =MAX(0,D3+E4-F4) | E4: =ROUND((B4-D3)*'Hypothèses'!B16,0) | F4: =ROUND(D3*'Hypothèses'!B17,0) | G4: =D4*('Hypothèses'!B20*'Hypothèses'!B18/12+(1-'Hypothèses'!B20)*'Hypothèses'!B19) | H4: =C4*'Hypothèses'!B22*'Hypothèses'!B21 | I4: =G4+H4 | J4: =(C4*1+D4*3)*'Hypothèses'!B8 | K4: ='Hypothèses'!B9 | L4: =I4-J4-K4 | M4: =M3+L4
A5: 4 | B5: =ROUND(B4*(1+'Hypothèses'!B4),0) | C5: =B5-D5 | D5: =MAX(0,D4+E5-F5) | E5: =ROUND((B5-D4)*'Hypothèses'!B16,0) | F5: =ROUND(D4*'Hypothèses'!B17,0) | G5: =D5*('Hypothèses'!B20*'Hypothèses'!B18/12+(1-'Hypothèses'!B20)*'Hypothèses'!B19) | H5: =C5*'Hypothèses'!B22*'Hypothèses'!B21 | I5: =G5+H5 | J5: =(C5*1+D5*3)*'Hypothèses'!B8 | K5: ='Hypothèses'!B9 | L5: =I5-J5-K5 | M5: =M4+L5
A6: 5 | B6: =ROUND(B5*(1+'Hypothèses'!B4),0) | C6: =B6-D6 | D6: =MAX(0,D5+E6-F6) | E6: =ROUND((B6-D5)*'Hypothèses'!B16,0) | F6: =ROUND(D5*'Hypothèses'!B17,0) | G6: =D6*('Hypothèses'!B20*'Hypothèses'!B18/12+(1-'Hypothèses'!B20)*'Hypothèses'!B19) | H6: =C6*'Hypothèses'!B22*'Hypothèses'!B21 | I6: =G6+H6 | J6: =(C6*1+D6*3)*'Hypothèses'!B8 | K6: ='Hypothèses'!B9 | L6: =I6-J6-K6 | M6: =M5+L6
A7: 6 | B7: =ROUND(B6*(1+'Hypothèses'!B4),0) | C7: =B7-D7 | D7: =MAX(0,D6+E7-F7) | E7: =ROUND((B7-D6)*'Hypothèses'!B16,0) | F7: =ROUND(D6*'Hypothèses'!B17,0) | G7: =D7*('Hypothèses'!B20*'Hypothèses'!B18/12+(1-'Hypothèses'!B20)*'Hypothèses'!B19) | H7: =C7*'Hypothèses'!B22*'Hypothèses'!B21 | I7: =G7+H7 | J7: =(C7*1+D7*3)*'Hypothèses'!B8 | K7: ='Hypothèses'!B9 | L7: =I7-J7-K7 | M7: =M6+L7
A8: 7 | B8: =ROUND(B7*(1+'Hypothèses'!B4),0) | C8: =B8-D8 | D8: =MAX(0,D7+E8-F8) | E8: =ROUND((B8-D7)*'Hypothèses'!B16,0) | F8: =ROUND(D7*'Hypothèses'!B17,0) | G8: =D8*('Hypothèses'!B20*'Hypothèses'!B18/12+(1-'Hypothèses'!B20)*'Hypothèses'!B19) | H8: =C8*'Hypothèses'!B22*'Hypothèses'!B21 | I8: =G8+H8 | J8: =(C8*1+D8*3)*'Hypothèses'!B8 | K8: ='Hypothèses'!B9 | L8: =I8-J8-K8 | M8: =M7+L8
A9: 8 | B9: =ROUND(B8*(1+'Hypothèses'!B4),0) | C9: =B9-D9 | D9: =MAX(0,D8+E9-F9) | E9: =ROUND((B9-D8)*'Hypothèses'!B16,0) | F9: =ROUND(D8*'Hypothèses'!B17,0) | G9: =D9*('Hypothèses'!B20*'Hypothèses'!B18/12+(1-'Hypothèses'!B20)*'Hypothèses'!B19) | H9: =C9*'Hypothèses'!B22*'Hypothèses'!B21 | I9: =G9+H9 | J9: =(C9*1+D9*3)*'Hypothèses'!B8 | K9: ='Hypothèses'!B9 | L9: =I9-J9-K9 | M9: =M8+L9
A10: 9 | B10: =ROUND(B9*(1+'Hypothèses'!B4),0) | C10: =B10-D10 | D10: =MAX(0,D9+E10-F10) | E10: =ROUND((B10-D9)*'Hypothèses'!B16,0) | F10: =ROUND(D9*'Hypothèses'!B17,0) | G10: =D10*('Hypothèses'!B20*'Hypothèses'!B18/12+(1-'Hypothèses'!B20)*'Hypothèses'!B19) | H10: =C10*'Hypothèses'!B22*'Hypothèses'!B21 | I10: =G10+H10 | J10: =(C10*1+D10*3)*'Hypothèses'!B8 | K10: ='Hypothèses'!B9 | L10: =I10-J10-K10 | M10: =M9+L10
A11: 10 | B11: =ROUND(B10*(1+'Hypothèses'!B4),0) | C11: =B11-D11 | D11: =MAX(0,D10+E11-F11) | E11: =ROUND((B11-D10)*'Hypothèses'!B16,0) | F11: =ROUND(D10*'Hypothèses'!B17,0) | G11: =D11*('Hypothèses'!B20*'Hypothèses'!B18/12+(1-'Hypothèses'!B20)*'Hypothèses'!B19) | H11: =C11*'Hypothèses'!B22*'Hypothèses'!B21 | I11: =G11+H11 | J11: =(C11*1+D11*3)*'Hypothèses'!B8 | K11: ='Hypothèses'!B9 | L11: =I11-J11-K11 | M11: =M10+L11
A12: 11 | B12: =ROUND(B11*(1+'Hypothèses'!B4),0) | C12: =B12-D12 | D12: =MAX(0,D11+E12-F12) | E12: =ROUND((B12-D11)*'Hypothèses'!B16,0) | F12: =ROUND(D11*'Hypothèses'!B17,0) | G12: =D12*('Hypothèses'!B20*'Hypothèses'!B18/12+(1-'Hypothèses'!B20)*'Hypothèses'!B19) | H12: =C12*'Hypothèses'!B22*'Hypothèses'!B21 | I12: =G12+H12 | J12: =(C12*1+D12*3)*'Hypothèses'!B8 | K12: ='Hypothèses'!B9 | L12: =I12-J12-K12 | M12: =M11+L12
A13: 12 | B13: =ROUND(B12*(1+'Hypothèses'!B4),0) | C13: =B13-D13 | D13: =MAX(0,D12+E13-F13) | E13: =ROUND((B13-D12)*'Hypothèses'!B16,0) | F13: =ROUND(D12*'Hypothèses'!B17,0) | G13: =D13*('Hypothèses'!B20*'Hypothèses'!B18/12+(1-'Hypothèses'!B20)*'Hypothèses'!B19) | H13: =C13*'Hypothèses'!B22*'Hypothèses'!B21 | I13: =G13+H13 | J13: =(C13*1+D13*3)*'Hypothèses'!B8 | K13: ='Hypothèses'!B9 | L13: =I13-J13-K13 | M13: =M12+L13
A14: 13 | B14: =ROUND(B13*(1+'Hypothèses'!B4),0) | C14: =B14-D14 | D14: =MAX(0,D13+E14-F14) | E14: =ROUND((B14-D13)*'Hypothèses'!B16,0) | F14: =ROUND(D13*'Hypothèses'!B17,0) | G14: =D14*('Hypothèses'!B20*'Hypothèses'!B18/12+(1-'Hypothèses'!B20)*'Hypothèses'!B19) | H14: =C14*'Hypothèses'!B22*'Hypothèses'!B21 | I14: =G14+H14 | J14: =(C14*1+D14*3)*'Hypothèses'!B8 | K14: ='Hypothèses'!B9 | L14: =I14-J14-K14 | M14: =M13+L14
A15: 14 | B15: =ROUND(B14*(1+'Hypothèses'!B4),0) | C15: =B15-D15 | D15: =MAX(0,D14+E15-F15) | E15: =ROUND((B15-D14)*'Hypothèses'!B16,0) | F15: =ROUND(D14*'Hypothèses'!B17,0) | G15: =D15*('Hypothèses'!B20*'Hypothèses'!B18/12+(1-'Hypothèses'!B20)*'Hypothèses'!B19) | H15: =C15*'Hypothèses'!B22*'Hypothèses'!B21 | I15: =G15+H15 | J15: =(C15*1+D15*3)*'Hypothèses'!B8 | K15: ='Hypothèses'!B9 | L15: =I15-J15-K15 | M15: =M14+L15
A16: 15 | B16: =ROUND(B15*(1+'Hypothèses'!B4),0) | C16: =B16-D16 | D16: =MAX(0,D15+E16-F16) | E16: =ROUND((B16-D15)*'Hypothèses'!B16,0) | F16: =ROUND(D15*'Hypothèses'!B17,0) | G16: =D16*('Hypothèses'!B20*'Hypothèses'!B18/12+(1-'Hypothèses'!B20)*'Hypothèses'!B19) | H16: =C16*'Hypothèses'!B22*'Hypothèses'!B21 | I16: =G16+H16 | J16: =(C16*1+D16*3)*'Hypothèses'!B8 | K16: ='Hypothèses'!B9 | L16: =I16-J16-K16 | M16: =M15+L16
A17: 16 | B17: =ROUND(B16*(1+'Hypothèses'!B4),0) | C17: =B17-D17 | D17: =MAX(0,D16+E17-F17) | E17: =ROUND((B17-D16)*'Hypothèses'!B16,0) | F17: =ROUND(D16*'Hypothèses'!B17,0) | G17: =D17*('Hypothèses'!B20*'Hypothèses'!B18/12+(1-'Hypothèses'!B20)*'Hypothèses'!B19) | H17: =C17*'Hypothèses'!B22*'Hypothèses'!B21 | I17: =G17+H17 | J17: =(C17*1+D17*3)*'Hypothèses'!B8 | K17: ='Hypothèses'!B9 | L17: =I17-J17-K17 | M17: =M16+L17
A18: 17 | B18: =ROUND(B17*(1+'Hypothèses'!B4),0) | C18: =B18-D18 | D18: =MAX(0,D17+E18-F18) | E18: =ROUND((B18-D17)*'Hypothèses'!B16,0) | F18: =ROUND(D17*'Hypothèses'!B17,0) | G18: =D18*('Hypothèses'!B20*'Hypothèses'!B18/12+(1-'Hypothèses'!B20)*'Hypothèses'!B19) | H18: =C18*'Hypothèses'!B22*'Hypothèses'!B21 | I18: =G18+H18 | J18: =(C18*1+D18*3)*'Hypothèses'!B8 | K18: ='Hypothèses'!B9 | L18: =I18-J18-K18 | M18: =M17+L18
A19: 18 | B19: =ROUND(B18*(1+'Hypothèses'!B4),0) | C19: =B19-D19 | D19: =MAX(0,D18+E19-F19) | E19: =ROUND((B19-D18)*'Hypothèses'!B16,0) | F19: =ROUND(D18*'Hypothèses'!B17,0) | G19: =D19*('Hypothèses'!B20*'Hypothèses'!B18/12+(1-'Hypothèses'!B20)*'Hypothèses'!B19) | H19: =C19*'Hypothèses'!B22*'Hypothèses'!B21 | I19: =G19+H19 | J19: =(C19*1+D19*3)*'Hypothèses'!B8 | K19: ='Hypothèses'!B9 | L19: =I19-J19-K19 | M19: =M18+L19
A20: 19 | B20: =ROUND(B19*(1+'Hypothèses'!B4),0) | C20: =B20-D20 | D20: =MAX(0,D19+E20-F20) | E20: =ROUND((B20-D19)*'Hypothèses'!B16,0) | F20: =ROUND(D19*'Hypothèses'!B17,0) | G20: =D20*('Hypothèses'!B20*'Hypothèses'!B18/12+(1-'Hypothèses'!B20)*'Hypothèses'!B19) | H20: =C20*'Hypothèses'!B22*'Hypothèses'!B21 | I20: =G20+H20 | J20: =(C20*1+D20*3)*'Hypothèses'!B8 | K20: ='Hypothèses'!B9 | L20: =I20-J20-K20 | M20: =M19+L20
A21: 20 | B21: =ROUND(B20*(1+'Hypothèses'!B4),0) | C21: =B21-D21 | D21: =MAX(0,D20+E21-F21) | E21: =ROUND((B21-D20)*'Hypothèses'!B16,0) | F21: =ROUND(D20*'Hypothèses'!B17,0) | G21: =D21*('Hypothèses'!B20*'Hypothèses'!B18/12+(1-'Hypothèses'!B20)*'Hypothèses'!B19) | H21: =C21*'Hypothèses'!B22*'Hypothèses'!B21 | I21: =G21+H21 | J21: =(C21*1+D21*3)*'Hypothèses'!B8 | K21: ='Hypothèses'!B9 | L21: =I21-J21-K21 | M21: =M20+L21
A22: 21 | B22: =ROUND(B21*(1+'Hypothèses'!B4),0) | C22: =B22-D22 | D22: =MAX(0,D21+E22-F22) | E22: =ROUND((B22-D21)*'Hypothèses'!B16,0) | F22: =ROUND(D21*'Hypothèses'!B17,0) | G22: =D22*('Hypothèses'!B20*'Hypothèses'!B18/12+(1-'Hypothèses'!B20)*'Hypothèses'!B19) | H22: =C22*'Hypothèses'!B22*'Hypothèses'!B21 | I22: =G22+H22 | J22: =(C22*1+D22*3)*'Hypothèses'!B8 | K22: ='Hypothèses'!B9 | L22: =I22-J22-K22 | M22: =M21+L22
A23: 22 | B23: =ROUND(B22*(1+'Hypothèses'!B4),0) | C23: =B23-D23 | D23: =MAX(0,D22+E23-F23) | E23: =ROUND((B23-D22)*'Hypothèses'!B16,0) | F23: =ROUND(D22*'Hypothèses'!B17,0) | G23: =D23*('Hypothèses'!B20*'Hypothèses'!B18/12+(1-'Hypothèses'!B20)*'Hypothèses'!B19) | H23: =C23*'Hypothèses'!B22*'Hypothèses'!B21 | I23: =G23+H23 | J23: =(C23*1+D23*3)*'Hypothèses'!B8 | K23: ='Hypothèses'!B9 | L23: =I23-J23-K23 | M23: =M22+L23
A24: 23 | B24: =ROUND(B23*(1+'Hypothèses'!B4),0) | C24: =B24-D24 | D24: =MAX(0,D23+E24-F24) | E24: =ROUND((B24-D23)*'Hypothèses'!B16,0) | F24: =ROUND(D23*'Hypothèses'!B17,0) | G24: =D24*('Hypothèses'!B20*'Hypothèses'!B18/12+(1-'Hypothèses'!B20)*'Hypothèses'!B19) | H24: =C24*'Hypothèses'!B22*'Hypothèses'!B21 | I24: =G24+H24 | J24: =(C24*1+D24*3)*'Hypothèses'!B8 | K24: ='Hypothèses'!B9 | L24: =I24-J24-K24 | M24: =M23+L24
A25: 24 | B25: =ROUND(B24*(1+'Hypothèses'!B4),0) | C25: =B25-D25 | D25: =MAX(0,D24+E25-F25) | E25: =ROUND((B25-D24)*'Hypothèses'!B16,0) | F25: =ROUND(D24*'Hypothèses'!B17,0) | G25: =D25*('Hypothèses'!B20*'Hypothèses'!B18/12+(1-'Hypothèses'!B20)*'Hypothèses'!B19) | H25: =C25*'Hypothèses'!B22*'Hypothèses'!B21 | I25: =G25+H25 | J25: =(C25*1+D25*3)*'Hypothèses'!B8 | K25: ='Hypothèses'!B9 | L25: =I25-J25-K25 | M25: =M24+L25

Sheet 2-Gratuit+Pub
A1: Mois | B1: Users totaux | C1: Users actifs | D1: Pages vues | E1: Impressions | F1: Revenu pub (€) | G1: Coût API (€) | H1: Coût serveur (€) | I1: Marge brute (€) | J1: Revenu cumulé (€)
A2: 1 | B2: ='Hypothèses'!B3 | C2: ='Hypothèses'!B3 | D2: =C2*'Hypothèses'!B26 | E2: =D2*'Hypothèses'!B27 | F2: =E2/1000*'Hypothèses'!B25 | G2: =C2*1*'Hypothèses'!B8 | H2: ='Hypothèses'!B9 | I2: =F2-G2-H2 | J2: =I2
A3: 2 | B3: =ROUND(B2*(1+'Hypothèses'!B4),0) | C3: =ROUND(C2*'Hypothèses'!B28+(B3-B2),0) | D3: =C3*'Hypothèses'!B26 | E3: =D3*'Hypothèses'!B27 | F3: =E3/1000*'Hypothèses'!B25 | G3: =C3*1*'Hypothèses'!B8 | H3: ='Hypothèses'!B9 | I3: =F3-G3-H3 | J3: =J2+I3
A4: 3 | B4: =ROUND(B3*(1+'Hypothèses'!B4),0) | C4: =ROUND(C3*'Hypothèses'!B28+(B4-B3),0) | D4: =C4*'Hypothèses'!B26 | E4: =D4*'Hypothèses'!B27 | F4: =E4/1000*'Hypothèses'!B25 | G4: =C4*1*'Hypothèses'!B8 | H4: ='Hypothèses'!B9 | I4: =F4-G4-H4 | J4: =J3+I4
A5: 4 | B5: =ROUND(B4*(1+'Hypothèses'!B4),0) | C5: =ROUND(C4*'Hypothèses'!B28+(B5-B4),0) | D5: =C5*'Hypothèses'!B26 | E5: =D5*'Hypothèses'!B27 | F5: =E5/1000*'Hypothèses'!B25 | G5: =C5*1*'Hypothèses'!B8 | H5: ='Hypothèses'!B9 | I5: =F5-G5-H5 | J5: =J4+I5
A6: 5 | B6: =ROUND(B5*(1+'Hypothèses'!B4),0) | C6: =ROUND(C5*'Hypothèses'!B28+(B6-B5),0) | D6: =C6*'Hypothèses'!B26 | E6: =D6*'Hypothèses'!B27 | F6: =E6/1000*'Hypothèses'!B25 | G6: =C6*1*'Hypothèses'!B8 | H6: ='Hypothèses'!B9 | I6: =F6-G6-H6 | J6: =J5+I6
A7: 6 | B7: =ROUND(B6*(1+'Hypothèses'!B4),0) | C7: =ROUND(C6*'Hypothèses'!B28+(B7-B6),0) | D7: =C7*'Hypothèses'!B26 | E7: =D7*'Hypothèses'!B27 | F7: =E7/1000*'Hypothèses'!B25 | G7: =C7*1*'Hypothèses'!B8 | H7: ='Hypothèses'!B9 | I7: =F7-G7-H7 | J7: =J6+I7
A8: 7 | B8: =ROUND(B7*(1+'Hypothèses'!B4),0) | C8: =ROUND(C7*'Hypothèses'!B28+(B8-B7),0) | D8: =C8*'Hypothèses'!B26 | E8: =D8*'Hypothèses'!B27 | F8: =E8/1000*'Hypothèses'!B25 | G8: =C8*1*'Hypothèses'!B8 | H8: ='Hypothèses'!B9 | I8: =F8-G8-H8 | J8: =J7+I8
A9: 8 | B9: =ROUND(B8*(1+'Hypothèses'!B4),0) | C9: =ROUND(C8*'Hypothèses'!B28+(B9-B8),0) | D9: =C9*'Hypothèses'!B26 | E9: =D9*'Hypothèses'!B27 | F9: =E9/1000*'Hypothèses'!B25 | G9: =C9*1*'Hypothèses'!B8 | H9: ='Hypothèses'!B9 | I9: =F9-G9-H9 | J9: =J8+I9
A10: 9 | B10: =ROUND(B9*(1+'Hypothèses'!B4),0) | C10: =ROUND(C9*'Hypothèses'!B28+(B10-B9),0) | D10: =C10*'Hypothèses'!B26 | E10: =D10*'Hypothèses'!B27 | F10: =E10/1000*'Hypothèses'!B25 | G10: =C10*1*'Hypothèses'!B8 | H10: ='Hypothèses'!B9 | I10: =F10-G10-H10 | J10: =J9+I10
A11: 10 | B11: =ROUND(B10*(1+'Hypothèses'!B4),0) | C11: =ROUND(C10*'Hypothèses'!B28+(B11-B10),0) | D11: =C11*'Hypothèses'!B26 | E11: =D11*'Hypothèses'!B27 | F11: =E11/1000*'Hypothèses'!B25 | G11: =C11*1*'Hypothèses'!B8 | H11: ='Hypothèses'!B9 | I11: =F11-G11-H11 | J11: =J10+I11
A12: 11 | B12: =ROUND(B11*(1+'Hypothèses'!B4),0) | C12: =ROUND(C11*'Hypothèses'!B28+(B12-B11),0) | D12: =C12*'Hypothèses'!B26 | E12: =D12*'Hypothèses'!B27 | F12: =E12/1000*'Hypothèses'!B25 | G12: =C12*1*'Hypothèses'!B8 | H12: ='Hypothèses'!B9 | I12: =F12-G12-H12 | J12: =J11+I12
A13: 12 | B13: =ROUND(B12*(1+'Hypothèses'!B4),0) | C13: =ROUND(C12*'Hypothèses'!B28+(B13-B12),0) | D13: =C13*'Hypothèses'!B26 | E13: =D13*'Hypothèses'!B27 | F13: =E13/1000*'Hypothèses'!B25 | G13: =C13*1*'Hypothèses'!B8 | H13: ='Hypothèses'!B9 | I13: =F13-G13-H13 | J13: =J12+I13
A14: 13 | B14: =ROUND(B13*(1+'Hypothèses'!B4),0) | C14: =ROUND(C13*'Hypothèses'!B28+(B14-B13),0) | D14: =C14*'Hypothèses'!B26 | E14: =D14*'Hypothèses'!B27 | F14: =E14/1000*'Hypothèses'!B25 | G14: =C14*1*'Hypothèses'!B8 | H14: ='Hypothèses'!B9 | I14: =F14-G14-H14 | J14: =J13+I14
A15: 14 | B15: =ROUND(B14*(1+'Hypothèses'!B4),0) | C15: =ROUND(C14*'Hypothèses'!B28+(B15-B14),0) | D15: =C15*'Hypothèses'!B26 | E15: =D15*'Hypothèses'!B27 | F15: =E15/1000*'Hypothèses'!B25 | G15: =C15*1*'Hypothèses'!B8 | H15: ='Hypothèses'!B9 | I15: =F15-G15-H15 | J15: =J14+I15
A16: 15 | B16: =ROUND(B15*(1+'Hypothèses'!B4),0) | C16: =ROUND(C15*'Hypothèses'!B28+(B16-B15),0) | D16: =C16*'Hypothèses'!B26 | E16: =D16*'Hypothèses'!B27 | F16: =E16/1000*'Hypothèses'!B25 | G16: =C16*1*'Hypothèses'!B8 | H16: ='Hypothèses'!B9 | I16: =F16-G16-H16 | J16: =J15+I16
A17: 16 | B17: =ROUND(B16*(1+'Hypothèses'!B4),0) | C17: =ROUND(C16*'Hypothèses'!B28+(B17-B16),0) | D17: =C17*'Hypothèses'!B26 | E17: =D17*'Hypothèses'!B27 | F17: =E17/1000*'Hypothèses'!B25 | G17: =C17*1*'Hypothèses'!B8 | H17: ='Hypothèses'!B9 | I17: =F17-G17-H17 | J17: =J16+I17
A18: 17 | B18: =ROUND(B17*(1+'Hypothèses'!B4),0) | C18: =ROUND(C17*'Hypothèses'!B28+(B18-B17),0) | D18: =C18*'Hypothèses'!B26 | E18: =D18*'Hypothèses'!B27 | F18: =E18/1000*'Hypothèses'!B25 | G18: =C18*1*'Hypothèses'!B8 | H18: ='Hypothèses'!B9 | I18: =F18-G18-H18 | J18: =J17+I18
A19: 18 | B19: =ROUND(B18*(1+'Hypothèses'!B4),0) | C19: =ROUND(C18*'Hypothèses'!B28+(B19-B18),0) | D19: =C19*'Hypothèses'!B26 | E19: =D19*'Hypothèses'!B27 | F19: =E19/1000*'Hypothèses'!B25 | G19: =C19*1*'Hypothèses'!B8 | H19: ='Hypothèses'!B9 | I19: =F19-G19-H19 | J19: =J18+I19
A20: 19 | B20: =ROUND(B19*(1+'Hypothèses'!B4),0) | C20: =ROUND(C19*'Hypothèses'!B28+(B20-B19),0) | D20: =C20*'Hypothèses'!B26 | E20: =D20*'Hypothèses'!B27 | F20: =E20/1000*'Hypothèses'!B25 | G20: =C20*1*'Hypothèses'!B8 | H20: ='Hypothèses'!B9 | I20: =F20-G20-H20 | J20: =J19+I20
A21: 20 | B21: =ROUND(B20*(1+'Hypothèses'!B4),0) | C21: =ROUND(C20*'Hypothèses'!B28+(B21-B20),0) | D21: =C21*'Hypothèses'!B26 | E21: =D21*'Hypothèses'!B27 | F21: =E21/1000*'Hypothèses'!B25 | G21: =C21*1*'Hypothèses'!B8 | H21: ='Hypothèses'!B9 | I21: =F21-G21-H21 | J21: =J20+I21
A22: 21 | B22: =ROUND(B21*(1+'Hypothèses'!B4),0) | C22: =ROUND(C21*'Hypothèses'!B28+(B22-B21),0) | D22: =C22*'Hypothèses'!B26 | E22: =D22*'Hypothèses'!B27 | F22: =E22/1000*'Hypothèses'!B25 | G22: =C22*1*'Hypothèses'!B8 | H22: ='Hypothèses'!B9 | I22: =F22-G22-H22 | J22: =J21+I22
A23: 22 | B23: =ROUND(B22*(1+'Hypothèses'!B4),0) | C23: =ROUND(C22*'Hypothèses'!B28+(B23-B22),0) | D23: =C23*'Hypothèses'!B26 | E23: =D23*'Hypothèses'!B27 | F23: =E23/1000*'Hypothèses'!B25 | G23: =C23*1*'Hypothèses'!B8 | H23: ='Hypothèses'!B9 | I23: =F23-G23-H23 | J23: =J22+I23
A24: 23 | B24: =ROUND(B23*(1+'Hypothèses'!B4),0) | C24: =ROUND(C23*'Hypothèses'!B28+(B24-B23),0) | D24: =C24*'Hypothèses'!B26 | E24: =D24*'Hypothèses'!B27 | F24: =E24/1000*'Hypothèses'!B25 | G24: =C24*1*'Hypothèses'!B8 | H24: ='Hypothèses'!B9 | I24: =F24-G24-H24 | J24: =J23+I24
A25: 24 | B25: =ROUND(B24*(1+'Hypothèses'!B4),0) | C25: =ROUND(C24*'Hypothèses'!B28+(B25-B24),0) | D25: =C25*'Hypothèses'!B26 | E25: =D25*'Hypothèses'!B27 | F25: =E25/1000*'Hypothèses'!B25 | G25: =C25*1*'Hypothèses'!B8 | H25: ='Hypothèses'!B9 | I25: =F25-G25-H25 | J25: =J24+I25

Sheet 3-Paiement unité
A1: Mois | B1: Users totaux | C1: Users actifs payants | D1: Voyages achetés | E1: Revenu (€) | F1: Coût API (€) | G1: Coût serveur (€) | H1: Marge brute (€) | I1: Revenu cumulé (€)
A2: 1 | B2: ='Hypothèses'!B3 | C2: =ROUND(B2*'Hypothèses'!B33,0) | D2: =ROUND(C2*'Hypothèses'!B32,0) | E2: =D2*'Hypothèses'!B31 | F2: =D2*'Hypothèses'!B8 | G2: ='Hypothèses'!B9 | H2: =E2-F2-G2 | I2: =H2
A3: 2 | B3: =ROUND(B2*(1+'Hypothèses'!B4),0) | C3: =ROUND((C2*'Hypothèses'!B34+(B3-B2)*'Hypothèses'!B33),0) | D3: =ROUND(C3*'Hypothèses'!B32,0) | E3: =D3*'Hypothèses'!B31 | F3: =D3*'Hypothèses'!B8 | G3: ='Hypothèses'!B9 | H3: =E3-F3-G3 | I3: =I2+H3
A4: 3 | B4: =ROUND(B3*(1+'Hypothèses'!B4),0) | C4: =ROUND((C3*'Hypothèses'!B34+(B4-B3)*'Hypothèses'!B33),0) | D4: =ROUND(C4*'Hypothèses'!B32,0) | E4: =D4*'Hypothèses'!B31 | F4: =D4*'Hypothèses'!B8 | G4: ='Hypothèses'!B9 | H4: =E4-F4-G4 | I4: =I3+H4
A5: 4 | B5: =ROUND(B4*(1+'Hypothèses'!B4),0) | C5: =ROUND((C4*'Hypothèses'!B34+(B5-B4)*'Hypothèses'!B33),0) | D5: =ROUND(C5*'Hypothèses'!B32,0) | E5: =D5*'Hypothèses'!B31 | F5: =D5*'Hypothèses'!B8 | G5: ='Hypothèses'!B9 | H5: =E5-F5-G5 | I5: =I4+H5
A6: 5 | B6: =ROUND(B5*(1+'Hypothèses'!B4),0) | C6: =ROUND((C5*'Hypothèses'!B34+(B6-B5)*'Hypothèses'!B33),0) | D6: =ROUND(C6*'Hypothèses'!B32,0) | E6: =D6*'Hypothèses'!B31 | F6: =D6*'Hypothèses'!B8 | G6: ='Hypothèses'!B9 | H6: =E6-F6-G6 | I6: =I5+H6
A7: 6 | B7: =ROUND(B6*(1+'Hypothèses'!B4),0) | C7: =ROUND((C6*'Hypothèses'!B34+(B7-B6)*'Hypothèses'!B33),0) | D7: =ROUND(C7*'Hypothèses'!B32,0) | E7: =D7*'Hypothèses'!B31 | F7: =D7*'Hypothèses'!B8 | G7: ='Hypothèses'!B9 | H7: =E7-F7-G7 | I7: =I6+H7
A8: 7 | B8: =ROUND(B7*(1+'Hypothèses'!B4),0) | C8: =ROUND((C7*'Hypothèses'!B34+(B8-B7)*'Hypothèses'!B33),0) | D8: =ROUND(C8*'Hypothèses'!B32,0) | E8: =D8*'Hypothèses'!B31 | F8: =D8*'Hypothèses'!B8 | G8: ='Hypothèses'!B9 | H8: =E8-F8-G8 | I8: =I7+H8
A9: 8 | B9: =ROUND(B8*(1+'Hypothèses'!B4),0) | C9: =ROUND((C8*'Hypothèses'!B34+(B9-B8)*'Hypothèses'!B33),0) | D9: =ROUND(C9*'Hypothèses'!B32,0) | E9: =D9*'Hypothèses'!B31 | F9: =D9*'Hypothèses'!B8 | G9: ='Hypothèses'!B9 | H9: =E9-F9-G9 | I9: =I8+H9
A10: 9 | B10: =ROUND(B9*(1+'Hypothèses'!B4),0) | C10: =ROUND((C9*'Hypothèses'!B34+(B10-B9)*'Hypothèses'!B33),0) | D10: =ROUND(C10*'Hypothèses'!B32,0) | E10: =D10*'Hypothèses'!B31 | F10: =D10*'Hypothèses'!B8 | G10: ='Hypothèses'!B9 | H10: =E10-F10-G10 | I10: =I9+H10
A11: 10 | B11: =ROUND(B10*(1+'Hypothèses'!B4),0) | C11: =ROUND((C10*'Hypothèses'!B34+(B11-B10)*'Hypothèses'!B33),0) | D11: =ROUND(C11*'Hypothèses'!B32,0) | E11: =D11*'Hypothèses'!B31 | F11: =D11*'Hypothèses'!B8 | G11: ='Hypothèses'!B9 | H11: =E11-F11-G11 | I11: =I10+H11
A12: 11 | B12: =ROUND(B11*(1+'Hypothèses'!B4),0) | C12: =ROUND((C11*'Hypothèses'!B34+(B12-B11)*'Hypothèses'!B33),0) | D12: =ROUND(C12*'Hypothèses'!B32,0) | E12: =D12*'Hypothèses'!B31 | F12: =D12*'Hypothèses'!B8 | G12: ='Hypothèses'!B9 | H12: =E12-F12-G12 | I12: =I11+H12
A13: 12 | B13: =ROUND(B12*(1+'Hypothèses'!B4),0) | C13: =ROUND((C12*'Hypothèses'!B34+(B13-B12)*'Hypothèses'!B33),0) | D13: =ROUND(C13*'Hypothèses'!B32,0) | E13: =D13*'Hypothèses'!B31 | F13: =D13*'Hypothèses'!B8 | G13: ='Hypothèses'!B9 | H13: =E13-F13-G13 | I13: =I12+H13
A14: 13 | B14: =ROUND(B13*(1+'Hypothèses'!B4),0) | C14: =ROUND((C13*'Hypothèses'!B34+(B14-B13)*'Hypothèses'!B33),0) | D14: =ROUND(C14*'Hypothèses'!B32,0) | E14: =D14*'Hypothèses'!B31 | F14: =D14*'Hypothèses'!B8 | G14: ='Hypothèses'!B9 | H14: =E14-F14-G14 | I14: =I13+H14
A15: 14 | B15: =ROUND(B14*(1+'Hypothèses'!B4),0) | C15: =ROUND((C14*'Hypothèses'!B34+(B15-B14)*'Hypothèses'!B33),0) | D15: =ROUND(C15*'Hypothèses'!B32,0) | E15: =D15*'Hypothèses'!B31 | F15: =D15*'Hypothèses'!B8 | G15: ='Hypothèses'!B9 | H15: =E15-F15-G15 | I15: =I14+H15
A16: 15 | B16: =ROUND(B15*(1+'Hypothèses'!B4),0) | C16: =ROUND((C15*'Hypothèses'!B34+(B16-B15)*'Hypothèses'!B33),0) | D16: =ROUND(C16*'Hypothèses'!B32,0) | E16: =D16*'Hypothèses'!B31 | F16: =D16*'Hypothèses'!B8 | G16: ='Hypothèses'!B9 | H16: =E16-F16-G16 | I16: =I15+H16
A17: 16 | B17: =ROUND(B16*(1+'Hypothèses'!B4),0) | C17: =ROUND((C16*'Hypothèses'!B34+(B17-B16)*'Hypothèses'!B33),0) | D17: =ROUND(C17*'Hypothèses'!B32,0) | E17: =D17*'Hypothèses'!B31 | F17: =D17*'Hypothèses'!B8 | G17: ='Hypothèses'!B9 | H17: =E17-F17-G17 | I17: =I16+H17
A18: 17 | B18: =ROUND(B17*(1+'Hypothèses'!B4),0) | C18: =ROUND((C17*'Hypothèses'!B34+(B18-B17)*'Hypothèses'!B33),0) | D18: =ROUND(C18*'Hypothèses'!B32,0) | E18: =D18*'Hypothèses'!B31 | F18: =D18*'Hypothèses'!B8 | G18: ='Hypothèses'!B9 | H18: =E18-F18-G18 | I18: =I17+H18
A19: 18 | B19: =ROUND(B18*(1+'Hypothèses'!B4),0) | C19: =ROUND((C18*'Hypothèses'!B34+(B19-B18)*'Hypothèses'!B33),0) | D19: =ROUND(C19*'Hypothèses'!B32,0) | E19: =D19*'Hypothèses'!B31 | F19: =D19*'Hypothèses'!B8 | G19: ='Hypothèses'!B9 | H19: =E19-F19-G19 | I19: =I18+H19
A20: 19 | B20: =ROUND(B19*(1+'Hypothèses'!B4),0) | C20: =ROUND((C19*'Hypothèses'!B34+(B20-B19)*'Hypothèses'!B33),0) | D20: =ROUND(C20*'Hypothèses'!B32,0) | E20: =D20*'Hypothèses'!B31 | F20: =D20*'Hypothèses'!B8 | G20: ='Hypothèses'!B9 | H20: =E20-F20-G20 | I20: =I19+H20
A21: 20 | B21: =ROUND(B20*(1+'Hypothèses'!B4),0) | C21: =ROUND((C20*'Hypothèses'!B34+(B21-B20)*'Hypothèses'!B33),0) | D21: =ROUND(C21*'Hypothèses'!B32,0) | E21: =D21*'Hypothèses'!B31 | F21: =D21*'Hypothèses'!B8 | G21: ='Hypothèses'!B9 | H21: =E21-F21-G21 | I21: =I20+H21
A22: 21 | B22: =ROUND(B21*(1+'Hypothèses'!B4),0) | C22: =ROUND((C21*'Hypothèses'!B34+(B22-B21)*'Hypothèses'!B33),0) | D22: =ROUND(C22*'Hypothèses'!B32,0) | E22: =D22*'Hypothèses'!B31 | F22: =D22*'Hypothèses'!B8 | G22: ='Hypothèses'!B9 | H22: =E22-F22-G22 | I22: =I21+H22
A23: 22 | B23: =ROUND(B22*(1+'Hypothèses'!B4),0) | C23: =ROUND((C22*'Hypothèses'!B34+(B23-B22)*'Hypothèses'!B33),0) | D23: =ROUND(C23*'Hypothèses'!B32,0) | E23: =D23*'Hypothèses'!B31 | F23: =D23*'Hypothèses'!B8 | G23: ='Hypothèses'!B9 | H23: =E23-F23-G23 | I23: =I22+H23
A24: 23 | B24: =ROUND(B23*(1+'Hypothèses'!B4),0) | C24: =ROUND((C23*'Hypothèses'!B34+(B24-B23)*'Hypothèses'!B33),0) | D24: =ROUND(C24*'Hypothèses'!B32,0) | E24: =D24*'Hypothèses'!B31 | F24: =D24*'Hypothèses'!B8 | G24: ='Hypothèses'!B9 | H24: =E24-F24-G24 | I24: =I23+H24
A25: 24 | B25: =ROUND(B24*(1+'Hypothèses'!B4),0) | C25: =ROUND((C24*'Hypothèses'!B34+(B25-B24)*'Hypothèses'!B33),0) | D25: =ROUND(C25*'Hypothèses'!B32,0) | E25: =D25*'Hypothèses'!B31 | F25: =D25*'Hypothèses'!B8 | G25: ='Hypothèses'!B9 | H25: =E25-F25-G25 | I25: =I24+H25

Sheet 4-Hybride
A1: Mois | B1: Users totaux | C1: Users free | D1: Users pro | E1: Revenu abo (€) | F1: Revenu pub (€) | G1: Revenu total (€) | H1: Coût API (€) | I1: Coût serveur (€) | J1: Marge brute (€) | K1: Revenu cumulé (€)
A2: 1 | B2: ='Hypothèses'!B3 | C2: =B2-D2 | D2: =ROUND(B2*'Hypothèses'!B37,0) | E2: =D2*'Hypothèses'!B39/12 | F2: =C2*'Hypothèses'!B41*'Hypothèses'!B42/1000*'Hypothèses'!B40 | G2: =E2+F2 | H2: =(C2*1+D2*3)*'Hypothèses'!B8 | I2: ='Hypothèses'!B9 | J2: =G2-H2-I2 | K2: =J2
A3: 2 | B3: =ROUND(B2*(1+'Hypothèses'!B4),0) | C3: =B3-D3 | D3: =MAX(0,ROUND(D2*(1-'Hypothèses'!B38)+(B3-B2)*'Hypothèses'!B37,0)) | E3: =D3*'Hypothèses'!B39/12 | F3: =C3*'Hypothèses'!B41*'Hypothèses'!B42/1000*'Hypothèses'!B40 | G3: =E3+F3 | H3: =(C3*1+D3*3)*'Hypothèses'!B8 | I3: ='Hypothèses'!B9 | J3: =G3-H3-I3 | K3: =K2+J3
A4: 3 | B4: =ROUND(B3*(1+'Hypothèses'!B4),0) | C4: =B4-D4 | D4: =MAX(0,ROUND(D3*(1-'Hypothèses'!B38)+(B4-B3)*'Hypothèses'!B37,0)) | E4: =D4*'Hypothèses'!B39/12 | F4: =C4*'Hypothèses'!B41*'Hypothèses'!B42/1000*'Hypothèses'!B40 | G4: =E4+F4 | H4: =(C4*1+D4*3)*'Hypothèses'!B8 | I4: ='Hypothèses'!B9 | J4: =G4-H4-I4 | K4: =K3+J4
A5: 4 | B5: =ROUND(B4*(1+'Hypothèses'!B4),0) | C5: =B5-D5 | D5: =MAX(0,ROUND(D4*(1-'Hypothèses'!B38)+(B5-B4)*'Hypothèses'!B37,0)) | E5: =D5*'Hypothèses'!B39/12 | F5: =C5*'Hypothèses'!B41*'Hypothèses'!B42/1000*'Hypothèses'!B40 | G5: =E5+F5 | H5: =(C5*1+D5*3)*'Hypothèses'!B8 | I5: ='Hypothèses'!B9 | J5: =G5-H5-I5 | K5: =K4+J5
A6: 5 | B6: =ROUND(B5*(1+'Hypothèses'!B4),0) | C6: =B6-D6 | D6: =MAX(0,ROUND(D5*(1-'Hypothèses'!B38)+(B6-B5)*'Hypothèses'!B37,0)) | E6: =D6*'Hypothèses'!B39/12 | F6: =C6*'Hypothèses'!B41*'Hypothèses'!B42/1000*'Hypothèses'!B40 | G6: =E6+F6 | H6: =(C6*1+D6*3)*'Hypothèses'!B8 | I6: ='Hypothèses'!B9 | J6: =G6-H6-I6 | K6: =K5+J6
A7: 6 | B7: =ROUND(B6*(1+'Hypothèses'!B4),0) | C7: =B7-D7 | D7: =MAX(0,ROUND(D6*(1-'Hypothèses'!B38)+(B7-B6)*'Hypothèses'!B37,0)) | E7: =D7*'Hypothèses'!B39/12 | F7: =C7*'Hypothèses'!B41*'Hypothèses'!B42/1000*'Hypothèses'!B40 | G7: =E7+F7 | H7: =(C7*1+D7*3)*'Hypothèses'!B8 | I7: ='Hypothèses'!B9 | J7: =G7-H7-I7 | K7: =K6+J7
A8: 7 | B8: =ROUND(B7*(1+'Hypothèses'!B4),0) | C8: =B8-D8 | D8: =MAX(0,ROUND(D7*(1-'Hypothèses'!B38)+(B8-B7)*'Hypothèses'!B37,0)) | E8: =D8*'Hypothèses'!B39/12 | F8: =C8*'Hypothèses'!B41*'Hypothèses'!B42/1000*'Hypothèses'!B40 | G8: =E8+F8 | H8: =(C8*1+D8*3)*'Hypothèses'!B8 | I8: ='Hypothèses'!B9 | J8: =G8-H8-I8 | K8: =K7+J8
A9: 8 | B9: =ROUND(B8*(1+'Hypothèses'!B4),0) | C9: =B9-D9 | D9: =MAX(0,ROUND(D8*(1-'Hypothèses'!B38)+(B9-B8)*'Hypothèses'!B37,0)) | E9: =D9*'Hypothèses'!B39/12 | F9: =C9*'Hypothèses'!B41*'Hypothèses'!B42/1000*'Hypothèses'!B40 | G9: =E9+F9 | H9: =(C9*1+D9*3)*'Hypothèses'!B8 | I9: ='Hypothèses'!B9 | J9: =G9-H9-I9 | K9: =K8+J9
A10: 9 | B10: =ROUND(B9*(1+'Hypothèses'!B4),0) | C10: =B10-D10 | D10: =MAX(0,ROUND(D9*(1-'Hypothèses'!B38)+(B10-B9)*'Hypothèses'!B37,0)) | E10: =D10*'Hypothèses'!B39/12 | F10: =C10*'Hypothèses'!B41*'Hypothèses'!B42/1000*'Hypothèses'!B40 | G10: =E10+F10 | H10: =(C10*1+D10*3)*'Hypothèses'!B8 | I10: ='Hypothèses'!B9 | J10: =G10-H10-I10 | K10: =K9+J10
A11: 10 | B11: =ROUND(B10*(1+'Hypothèses'!B4),0) | C11: =B11-D11 | D11: =MAX(0,ROUND(D10*(1-'Hypothèses'!B38)+(B11-B10)*'Hypothèses'!B37,0)) | E11: =D11*'Hypothèses'!B39/12 | F11: =C11*'Hypothèses'!B41*'Hypothèses'!B42/1000*'Hypothèses'!B40 | G11: =E11+F11 | H11: =(C11*1+D11*3)*'Hypothèses'!B8 | I11: ='Hypothèses'!B9 | J11: =G11-H11-I11 | K11: =K10+J11
A12: 11 | B12: =ROUND(B11*(1+'Hypothèses'!B4),0) | C12: =B12-D12 | D12: =MAX(0,ROUND(D11*(1-'Hypothèses'!B38)+(B12-B11)*'Hypothèses'!B37,0)) | E12: =D12*'Hypothèses'!B39/12 | F12: =C12*'Hypothèses'!B41*'Hypothèses'!B42/1000*'Hypothèses'!B40 | G12: =E12+F12 | H12: =(C12*1+D12*3)*'Hypothèses'!B8 | I12: ='Hypothèses'!B9 | J12: =G12-H12-I12 | K12: =K11+J12
A13: 12 | B13: =ROUND(B12*(1+'Hypothèses'!B4),0) | C13: =B13-D13 | D13: =MAX(0,ROUND(D12*(1-'Hypothèses'!B38)+(B13-B12)*'Hypothèses'!B37,0)) | E13: =D13*'Hypothèses'!B39/12 | F13: =C13*'Hypothèses'!B41*'Hypothèses'!B42/1000*'Hypothèses'!B40 | G13: =E13+F13 | H13: =(C13*1+D13*3)*'Hypothèses'!B8 | I13: ='Hypothèses'!B9 | J13: =G13-H13-I13 | K13: =K12+J13
A14: 13 | B14: =ROUND(B13*(1+'Hypothèses'!B4),0) | C14: =B14-D14 | D14: =MAX(0,ROUND(D13*(1-'Hypothèses'!B38)+(B14-B13)*'Hypothèses'!B37,0)) | E14: =D14*'Hypothèses'!B39/12 | F14: =C14*'Hypothèses'!B41*'Hypothèses'!B42/1000*'Hypothèses'!B40 | G14: =E14+F14 | H14: =(C14*1+D14*3)*'Hypothèses'!B8 | I14: ='Hypothèses'!B9 | J14: =G14-H14-I14 | K14: =K13+J14
A15: 14 | B15: =ROUND(B14*(1+'Hypothèses'!B4),0) | C15: =B15-D15 | D15: =MAX(0,ROUND(D14*(1-'Hypothèses'!B38)+(B15-B14)*'Hypothèses'!B37,0)) | E15: =D15*'Hypothèses'!B39/12 | F15: =C15*'Hypothèses'!B41*'Hypothèses'!B42/1000*'Hypothèses'!B40 | G15: =E15+F15 | H15: =(C15*1+D15*3)*'Hypothèses'!B8 | I15: ='Hypothèses'!B9 | J15: =G15-H15-I15 | K15: =K14+J15
A16: 15 | B16: =ROUND(B15*(1+'Hypothèses'!B4),0) | C16: =B16-D16 | D16: =MAX(0,ROUND(D15*(1-'Hypothèses'!B38)+(B16-B15)*'Hypothèses'!B37,0)) | E16: =D16*'Hypothèses'!B39/12 | F16: =C16*'Hypothèses'!B41*'Hypothèses'!B42/1000*'Hypothèses'!B40 | G16: =E16+F16 | H16: =(C16*1+D16*3)*'Hypothèses'!B8 | I16: ='Hypothèses'!B9 | J16: =G16-H16-I16 | K16: =K15+J16
A17: 16 | B17: =ROUND(B16*(1+'Hypothèses'!B4),0) | C17: =B17-D17 | D17: =MAX(0,ROUND(D16*(1-'Hypothèses'!B38)+(B17-B16)*'Hypothèses'!B37,0)) | E17: =D17*'Hypothèses'!B39/12 | F17: =C17*'Hypothèses'!B41*'Hypothèses'!B42/1000*'Hypothèses'!B40 | G17: =E17+F17 | H17: =(C17*1+D17*3)*'Hypothèses'!B8 | I17: ='Hypothèses'!B9 | J17: =G17-H17-I17 | K17: =K16+J17
A18: 17 | B18: =ROUND(B17*(1+'Hypothèses'!B4),0) | C18: =B18-D18 | D18: =MAX(0,ROUND(D17*(1-'Hypothèses'!B38)+(B18-B17)*'Hypothèses'!B37,0)) | E18: =D18*'Hypothèses'!B39/12 | F18: =C18*'Hypothèses'!B41*'Hypothèses'!B42/1000*'Hypothèses'!B40 | G18: =E18+F18 | H18: =(C18*1+D18*3)*'Hypothèses'!B8 | I18: ='Hypothèses'!B9 | J18: =G18-H18-I18 | K18: =K17+J18
A19: 18 | B19: =ROUND(B18*(1+'Hypothèses'!B4),0) | C19: =B19-D19 | D19: =MAX(0,ROUND(D18*(1-'Hypothèses'!B38)+(B19-B18)*'Hypothèses'!B37,0)) | E19: =D19*'Hypothèses'!B39/12 | F19: =C19*'Hypothèses'!B41*'Hypothèses'!B42/1000*'Hypothèses'!B40 | G19: =E19+F19 | H19: =(C19*1+D19*3)*'Hypothèses'!B8 | I19: ='Hypothèses'!B9 | J19: =G19-H19-I19 | K19: =K18+J19
A20: 19 | B20: =ROUND(B19*(1+'Hypothèses'!B4),0) | C20: =B20-D20 | D20: =MAX(0,ROUND(D19*(1-'Hypothèses'!B38)+(B20-B19)*'Hypothèses'!B37,0)) | E20: =D20*'Hypothèses'!B39/12 | F20: =C20*'Hypothèses'!B41*'Hypothèses'!B42/1000*'Hypothèses'!B40 | G20: =E20+F20 | H20: =(C20*1+D20*3)*'Hypothèses'!B8 | I20: ='Hypothèses'!B9 | J20: =G20-H20-I20 | K20: =K19+J20
A21: 20 | B21: =ROUND(B20*(1+'Hypothèses'!B4),0) | C21: =B21-D21 | D21: =MAX(0,ROUND(D20*(1-'Hypothèses'!B38)+(B21-B20)*'Hypothèses'!B37,0)) | E21: =D21*'Hypothèses'!B39/12 | F21: =C21*'Hypothèses'!B41*'Hypothèses'!B42/1000*'Hypothèses'!B40 | G21: =E21+F21 | H21: =(C21*1+D21*3)*'Hypothèses'!B8 | I21: ='Hypothèses'!B9 | J21: =G21-H21-I21 | K21: =K20+J21
A22: 21 | B22: =ROUND(B21*(1+'Hypothèses'!B4),0) | C22: =B22-D22 | D22: =MAX(0,ROUND(D21*(1-'Hypothèses'!B38)+(B22-B21)*'Hypothèses'!B37,0)) | E22: =D22*'Hypothèses'!B39/12 | F22: =C22*'Hypothèses'!B41*'Hypothèses'!B42/1000*'Hypothèses'!B40 | G22: =E22+F22 | H22: =(C22*1+D22*3)*'Hypothèses'!B8 | I22: ='Hypothèses'!B9 | J22: =G22-H22-I22 | K22: =K21+J22
A23: 22 | B23: =ROUND(B22*(1+'Hypothèses'!B4),0) | C23: =B23-D23 | D23: =MAX(0,ROUND(D22*(1-'Hypothèses'!B38)+(B23-B22)*'Hypothèses'!B37,0)) | E23: =D23*'Hypothèses'!B39/12 | F23: =C23*'Hypothèses'!B41*'Hypothèses'!B42/1000*'Hypothèses'!B40 | G23: =E23+F23 | H23: =(C23*1+D23*3)*'Hypothèses'!B8 | I23: ='Hypothèses'!B9 | J23: =G23-H23-I23 | K23: =K22+J23
A24: 23 | B24: =ROUND(B23*(1+'Hypothèses'!B4),0) | C24: =B24-D24 | D24: =MAX(0,ROUND(D23*(1-'Hypothèses'!B38)+(B24-B23)*'Hypothèses'!B37,0)) | E24: =D24*'Hypothèses'!B39/12 | F24: =C24*'Hypothèses'!B41*'Hypothèses'!B42/1000*'Hypothèses'!B40 | G24: =E24+F24 | H24: =(C24*1+D24*3)*'Hypothèses'!B8 | I24: ='Hypothèses'!B9 | J24: =G24-H24-I24 | K24: =K23+J24
A25: 24 | B25: =ROUND(B24*(1+'Hypothèses'!B4),0) | C25: =B25-D25 | D25: =MAX(0,ROUND(D24*(1-'Hypothèses'!B38)+(B25-B24)*'Hypothèses'!B37,0)) | E25: =D25*'Hypothèses'!B39/12 | F25: =C25*'Hypothèses'!B41*'Hypothèses'!B42/1000*'Hypothèses'!B40 | G25: =E25+F25 | H25: =(C25*1+D25*3)*'Hypothèses'!B8 | I25: ='Hypothèses'!B9 | J25: =G25-H25-I25 | K25: =K24+J25

Sheet 5-Affiliés
A1: Mois | B1: Users totaux | C1: Voyages générés | D1: Liens affiliés affichés | E1: Clics | F1: Bookings convertis | G1: Revenu commissions (€) | H1: Coût API (€) | I1: Coût serveur (€) | J1: Marge brute (€) | K1: Revenu cumulé (€)
A2: 1 | B2: ='Hypothèses'!B3 | C2: =B2*'Hypothèses'!B49 | D2: =C2*'Hypothèses'!B48 | E2: =ROUND(D2*'Hypothèses'!B45,0) | F2: =ROUND(E2*'Hypothèses'!B46,0) | G2: =F2*'Hypothèses'!B47 | H2: =C2*'Hypothèses'!B8 | I2: ='Hypothèses'!B9 | J2: =G2-H2-I2 | K2: =J2
A3: 2 | B3: =ROUND(B2*(1+'Hypothèses'!B4),0) | C3: =B3*'Hypothèses'!B49 | D3: =C3*'Hypothèses'!B48 | E3: =ROUND(D3*'Hypothèses'!B45,0) | F3: =ROUND(E3*'Hypothèses'!B46,0) | G3: =F3*'Hypothèses'!B47 | H3: =C3*'Hypothèses'!B8 | I3: ='Hypothèses'!B9 | J3: =G3-H3-I3 | K3: =K2+J3
A4: 3 | B4: =ROUND(B3*(1+'Hypothèses'!B4),0) | C4: =B4*'Hypothèses'!B49 | D4: =C4*'Hypothèses'!B48 | E4: =ROUND(D4*'Hypothèses'!B45,0) | F4: =ROUND(E4*'Hypothèses'!B46,0) | G4: =F4*'Hypothèses'!B47 | H4: =C4*'Hypothèses'!B8 | I4: ='Hypothèses'!B9 | J4: =G4-H4-I4 | K4: =K3+J4
A5: 4 | B5: =ROUND(B4*(1+'Hypothèses'!B4),0) | C5: =B5*'Hypothèses'!B49 | D5: =C5*'Hypothèses'!B48 | E5: =ROUND(D5*'Hypothèses'!B45,0) | F5: =ROUND(E5*'Hypothèses'!B46,0) | G5: =F5*'Hypothèses'!B47 | H5: =C5*'Hypothèses'!B8 | I5: ='Hypothèses'!B9 | J5: =G5-H5-I5 | K5: =K4+J5
A6: 5 | B6: =ROUND(B5*(1+'Hypothèses'!B4),0) | C6: =B6*'Hypothèses'!B49 | D6: =C6*'Hypothèses'!B48 | E6: =ROUND(D6*'Hypothèses'!B45,0) | F6: =ROUND(E6*'Hypothèses'!B46,0) | G6: =F6*'Hypothèses'!B47 | H6: =C6*'Hypothèses'!B8 | I6: ='Hypothèses'!B9 | J6: =G6-H6-I6 | K6: =K5+J6
A7: 6 | B7: =ROUND(B6*(1+'Hypothèses'!B4),0) | C7: =B7*'Hypothèses'!B49 | D7: =C7*'Hypothèses'!B48 | E7: =ROUND(D7*'Hypothèses'!B45,0) | F7: =ROUND(E7*'Hypothèses'!B46,0) | G7: =F7*'Hypothèses'!B47 | H7: =C7*'Hypothèses'!B8 | I7: ='Hypothèses'!B9 | J7: =G7-H7-I7 | K7: =K6+J7
A8: 7 | B8: =ROUND(B7*(1+'Hypothèses'!B4),0) | C8: =B8*'Hypothèses'!B49 | D8: =C8*'Hypothèses'!B48 | E8: =ROUND(D8*'Hypothèses'!B45,0) | F8: =ROUND(E8*'Hypothèses'!B46,0) | G8: =F8*'Hypothèses'!B47 | H8: =C8*'Hypothèses'!B8 | I8: ='Hypothèses'!B9 | J8: =G8-H8-I8 | K8: =K7+J8
A9: 8 | B9: =ROUND(B8*(1+'Hypothèses'!B4),0) | C9: =B9*'Hypothèses'!B49 | D9: =C9*'Hypothèses'!B48 | E9: =ROUND(D9*'Hypothèses'!B45,0) | F9: =ROUND(E9*'Hypothèses'!B46,0) | G9: =F9*'Hypothèses'!B47 | H9: =C9*'Hypothèses'!B8 | I9: ='Hypothèses'!B9 | J9: =G9-H9-I9 | K9: =K8+J9
A10: 9 | B10: =ROUND(B9*(1+'Hypothèses'!B4),0) | C10: =B10*'Hypothèses'!B49 | D10: =C10*'Hypothèses'!B48 | E10: =ROUND(D10*'Hypothèses'!B45,0) | F10: =ROUND(E10*'Hypothèses'!B46,0) | G10: =F10*'Hypothèses'!B47 | H10: =C10*'Hypothèses'!B8 | I10: ='Hypothèses'!B9 | J10: =G10-H10-I10 | K10: =K9+J10
A11: 10 | B11: =ROUND(B10*(1+'Hypothèses'!B4),0) | C11: =B11*'Hypothèses'!B49 | D11: =C11*'Hypothèses'!B48 | E11: =ROUND(D11*'Hypothèses'!B45,0) | F11: =ROUND(E11*'Hypothèses'!B46,0) | G11: =F11*'Hypothèses'!B47 | H11: =C11*'Hypothèses'!B8 | I11: ='Hypothèses'!B9 | J11: =G11-H11-I11 | K11: =K10+J11
A12: 11 | B12: =ROUND(B11*(1+'Hypothèses'!B4),0) | C12: =B12*'Hypothèses'!B49 | D12: =C12*'Hypothèses'!B48 | E12: =ROUND(D12*'Hypothèses'!B45,0) | F12: =ROUND(E12*'Hypothèses'!B46,0) | G12: =F12*'Hypothèses'!B47 | H12: =C12*'Hypothèses'!B8 | I12: ='Hypothèses'!B9 | J12: =G12-H12-I12 | K12: =K11+J12
A13: 12 | B13: =ROUND(B12*(1+'Hypothèses'!B4),0) | C13: =B13*'Hypothèses'!B49 | D13: =C13*'Hypothèses'!B48 | E13: =ROUND(D13*'Hypothèses'!B45,0) | F13: =ROUND(E13*'Hypothèses'!B46,0) | G13: =F13*'Hypothèses'!B47 | H13: =C13*'Hypothèses'!B8 | I13: ='Hypothèses'!B9 | J13: =G13-H13-I13 | K13: =K12+J13
A14: 13 | B14: =ROUND(B13*(1+'Hypothèses'!B4),0) | C14: =B14*'Hypothèses'!B49 | D14: =C14*'Hypothèses'!B48 | E14: =ROUND(D14*'Hypothèses'!B45,0) | F14: =ROUND(E14*'Hypothèses'!B46,0) | G14: =F14*'Hypothèses'!B47 | H14: =C14*'Hypothèses'!B8 | I14: ='Hypothèses'!B9 | J14: =G14-H14-I14 | K14: =K13+J14
A15: 14 | B15: =ROUND(B14*(1+'Hypothèses'!B4),0) | C15: =B15*'Hypothèses'!B49 | D15: =C15*'Hypothèses'!B48 | E15: =ROUND(D15*'Hypothèses'!B45,0) | F15: =ROUND(E15*'Hypothèses'!B46,0) | G15: =F15*'Hypothèses'!B47 | H15: =C15*'Hypothèses'!B8 | I15: ='Hypothèses'!B9 | J15: =G15-H15-I15 | K15: =K14+J15
A16: 15 | B16: =ROUND(B15*(1+'Hypothèses'!B4),0) | C16: =B16*'Hypothèses'!B49 | D16: =C16*'Hypothèses'!B48 | E16: =ROUND(D16*'Hypothèses'!B45,0) | F16: =ROUND(E16*'Hypothèses'!B46,0) | G16: =F16*'Hypothèses'!B47 | H16: =C16*'Hypothèses'!B8 | I16: ='Hypothèses'!B9 | J16: =G16-H16-I16 | K16: =K15+J16
A17: 16 | B17: =ROUND(B16*(1+'Hypothèses'!B4),0) | C17: =B17*'Hypothèses'!B49 | D17: =C17*'Hypothèses'!B48 | E17: =ROUND(D17*'Hypothèses'!B45,0) | F17: =ROUND(E17*'Hypothèses'!B46,0) | G17: =F17*'Hypothèses'!B47 | H17: =C17*'Hypothèses'!B8 | I17: ='Hypothèses'!B9 | J17: =G17-H17-I17 | K17: =K16+J17
A18: 17 | B18: =ROUND(B17*(1+'Hypothèses'!B4),0) | C18: =B18*'Hypothèses'!B49 | D18: =C18*'Hypothèses'!B48 | E18: =ROUND(D18*'Hypothèses'!B45,0) | F18: =ROUND(E18*'Hypothèses'!B46,0) | G18: =F18*'Hypothèses'!B47 | H18: =C18*'Hypothèses'!B8 | I18: ='Hypothèses'!B9 | J18: =G18-H18-I18 | K18: =K17+J18
A19: 18 | B19: =ROUND(B18*(1+'Hypothèses'!B4),0) | C19: =B19*'Hypothèses'!B49 | D19: =C19*'Hypothèses'!B48 | E19: =ROUND(D19*'Hypothèses'!B45,0) | F19: =ROUND(E19*'Hypothèses'!B46,0) | G19: =F19*'Hypothèses'!B47 | H19: =C19*'Hypothèses'!B8 | I19: ='Hypothèses'!B9 | J19: =G19-H19-I19 | K19: =K18+J19
A20: 19 | B20: =ROUND(B19*(1+'Hypothèses'!B4),0) | C20: =B20*'Hypothèses'!B49 | D20: =C20*'Hypothèses'!B48 | E20: =ROUND(D20*'Hypothèses'!B45,0) | F20: =ROUND(E20*'Hypothèses'!B46,0) | G20: =F20*'Hypothèses'!B47 | H20: =C20*'Hypothèses'!B8 | I20: ='Hypothèses'!B9 | J20: =G20-H20-I20 | K20: =K19+J20
A21: 20 | B21: =ROUND(B20*(1+'Hypothèses'!B4),0) | C21: =B21*'Hypothèses'!B49 | D21: =C21*'Hypothèses'!B48 | E21: =ROUND(D21*'Hypothèses'!B45,0) | F21: =ROUND(E21*'Hypothèses'!B46,0) | G21: =F21*'Hypothèses'!B47 | H21: =C21*'Hypothèses'!B8 | I21: ='Hypothèses'!B9 | J21: =G21-H21-I21 | K21: =K20+J21
A22: 21 | B22: =ROUND(B21*(1+'Hypothèses'!B4),0) | C22: =B22*'Hypothèses'!B49 | D22: =C22*'Hypothèses'!B48 | E22: =ROUND(D22*'Hypothèses'!B45,0) | F22: =ROUND(E22*'Hypothèses'!B46,0) | G22: =F22*'Hypothèses'!B47 | H22: =C22*'Hypothèses'!B8 | I22: ='Hypothèses'!B9 | J22: =G22-H22-I22 | K22: =K21+J22
A23: 22 | B23: =ROUND(B22*(1+'Hypothèses'!B4),0) | C23: =B23*'Hypothèses'!B49 | D23: =C23*'Hypothèses'!B48 | E23: =ROUND(D23*'Hypothèses'!B45,0) | F23: =ROUND(E23*'Hypothèses'!B46,0) | G23: =F23*'Hypothèses'!B47 | H23: =C23*'Hypothèses'!B8 | I23: ='Hypothèses'!B9 | J23: =G23-H23-I23 | K23: =K22+J23
A24: 23 | B24: =ROUND(B23*(1+'Hypothèses'!B4),0) | C24: =B24*'Hypothèses'!B49 | D24: =C24*'Hypothèses'!B48 | E24: =ROUND(D24*'Hypothèses'!B45,0) | F24: =ROUND(E24*'Hypothèses'!B46,0) | G24: =F24*'Hypothèses'!B47 | H24: =C24*'Hypothèses'!B8 | I24: ='Hypothèses'!B9 | J24: =G24-H24-I24 | K24: =K23+J24
A25: 24 | B25: =ROUND(B24*(1+'Hypothèses'!B4),0) | C25: =B25*'Hypothèses'!B49 | D25: =C25*'Hypothèses'!B48 | E25: =ROUND(D25*'Hypothèses'!B45,0) | F25: =ROUND(E25*'Hypothèses'!B46,0) | G25: =F25*'Hypothèses'!B47 | H25: =C25*'Hypothèses'!B8 | I25: ='Hypothèses'!B9 | J25: =G25-H25-I25 | K25: =K24+J25

Sheet Comparaison
A1: COMPARAISON DES 5 MODÈLES
A3: À 6 mois
A4: Métrique | B4: Freemium+Abo | C4: Gratuit+Pub | D4: Paiement unité | E4: Hybride Abo+Pub | F4: Affiliés
A5: Users totaux | B5: ='1-Freemium+Abo'!B7 | C5: ='2-Gratuit+Pub'!B7 | D5: ='3-Paiement unité'!B7 | E5: ='4-Hybride'!B7 | F5: ='5-Affiliés'!B7
A6: Revenu cumulé (marge) | B6: ='1-Freemium+Abo'!M7 | C6: ='2-Gratuit+Pub'!J7 | D6: ='3-Paiement unité'!I7 | E6: ='4-Hybride'!K7 | F6: ='5-Affiliés'!K7
A7: Marge mensuelle | B7: ='1-Freemium+Abo'!L7 | C7: ='2-Gratuit+Pub'!I7 | D7: ='3-Paiement unité'!H7 | E7: ='4-Hybride'!J7 | F7: ='5-Affiliés'!J7
A8: ARPU mensuel | B8: =IF('1-Freemium+Abo'!B7>0,'1-Freemium+Abo'!I7/'1-Freemium+Abo'!B7,0) | C8: =IF('2-Gratuit+Pub'!B7>0,'2-Gratuit+Pub'!F7/'2-Gratuit+Pub'!B7,0) | D8: =IF('3-Paiement unité'!B7>0,'3-Paiement unité'!E7/'3-Paiement unité'!B7,0) | E8: =IF('4-Hybride'!B7>0,'4-Hybride'!G7/'4-Hybride'!B7,0) | F8: =IF('5-Affiliés'!B7>0,'5-Affiliés'!G7/'5-Affiliés'!B7,0)
A10: À 12 mois
A11: Métrique | B11: Freemium+Abo | C11: Gratuit+Pub | D11: Paiement unité | E11: Hybride Abo+Pub | F11: Affiliés
A12: Users totaux | B12: ='1-Freemium+Abo'!B13 | C12: ='2-Gratuit+Pub'!B13 | D12: ='3-Paiement unité'!B13 | E12: ='4-Hybride'!B13 | F12: ='5-Affiliés'!B13
A13: Revenu cumulé (marge) | B13: ='1-Freemium+Abo'!M13 | C13: ='2-Gratuit+Pub'!J13 | D13: ='3-Paiement unité'!I13 | E13: ='4-Hybride'!K13 | F13: ='5-Affiliés'!K13
A14: Marge mensuelle | B14: ='1-Freemium+Abo'!L13 | C14: ='2-Gratuit+Pub'!I13 | D14: ='3-Paiement unité'!H13 | E14: ='4-Hybride'!J13 | F14: ='5-Affiliés'!J13
A15: ARPU mensuel | B15: =IF('1-Freemium+Abo'!B13>0,'1-Freemium+Abo'!I13/'1-Freemium+Abo'!B13,0) | C15: =IF('2-Gratuit+Pub'!B13>0,'2-Gratuit+Pub'!F13/'2-Gratuit+Pub'!B13,0) | D15: =IF('3-Paiement unité'!B13>0,'3-Paiement unité'!E13/'3-Paiement unité'!B13,0) | E15: =IF('4-Hybride'!B13>0,'4-Hybride'!G13/'4-Hybride'!B13,0) | F15: =IF('5-Affiliés'!B13>0,'5-Affiliés'!G13/'5-Affiliés'!B13,0)
A17: À 24 mois
A18: Métrique | B18: Freemium+Abo | C18: Gratuit+Pub | D18: Paiement unité | E18: Hybride Abo+Pub | F18: Affiliés
A19: Users totaux | B19: ='1-Freemium+Abo'!B25 | C19: ='2-Gratuit+Pub'!B25 | D19: ='3-Paiement unité'!B25 | E19: ='4-Hybride'!B25 | F19: ='5-Affiliés'!B25
A20: Revenu cumulé (marge) | B20: ='1-Freemium+Abo'!M25 | C20: ='2-Gratuit+Pub'!J25 | D20: ='3-Paiement unité'!I25 | E20: ='4-Hybride'!K25 | F20: ='5-Affiliés'!K25
A21: Marge mensuelle | B21: ='1-Freemium+Abo'!L25 | C21: ='2-Gratuit+Pub'!I25 | D21: ='3-Paiement unité'!H25 | E21: ='4-Hybride'!J25 | F21: ='5-Affiliés'!J25
A22: ARPU mensuel | B22: =IF('1-Freemium+Abo'!B25>0,'1-Freemium+Abo'!I25/'1-Freemium+Abo'!B25,0) | C22: =IF('2-Gratuit+Pub'!B25>0,'2-Gratuit+Pub'!F25/'2-Gratuit+Pub'!B25,0) | D22: =IF('3-Paiement unité'!B25>0,'3-Paiement unité'!E25/'3-Paiement unité'!B25,0) | E22: =IF('4-Hybride'!B25>0,'4-Hybride'!G25/'4-Hybride'!B25,0) | F22: =IF('5-Affiliés'!B25>0,'5-Affiliés'!G25/'5-Affiliés'!B25,0)
A24: RECOMMANDATIONS
A25: 1. Le modèle actuel (Freemium+Abo) est solide mais les coûts API (~0.40€/voyage) mangent la marge.
A26: 2. Paiement à l'unité génère le plus de revenu mais la rétention est le risque principal.
A27: 3. La pub seule ne couvre PAS les coûts API - le CPM web est trop bas.
A28: 4. Les affiliés seuls ne sont pas viables (commissions trop faibles vs coûts).
A29: 5. Action recommandée : augmenter le prix Pro à 19.99€/an et réduire les coûts API (cache, batch).
A30: 6. Modifier les cellules jaunes dans l'onglet Hypothèses pour tester vos scénarios.
